Workbook
Name display_week: 'Gantt Chart'!$M$5
Name task_start: 'Gantt Chart'!$M$4

Sheet Calculations
C1: CALCULATIONS/AUTOMATIONS
C3: Selected Year | H3: Date Today
C4: =Dashboard!T2 -> 2024 | H4: =TODAY() -> 46232
H5: =H4 -> 46232
C6: Selected Month | H6: =TODAY() -> 46232
C7: =Dashboard!Q2 -> January
C9: =MONTH(DATE(2023, MATCH(C7, {"January","February","March","April","May","June","July","August","September","October","November","December"}, 0), 1)) -> 1
C10: Monthly Performance Breakdown | H10: Tasks Due By Category (Selected Month) | M10: Tasks Due By Priority (Selected Month) | R10: Tasks Due By Department (Selected Month) | W10: Tasks Due By Status (Selected Month) | AB10: Current Performance (Last 7 Days)
C11: Date | D11: Total Tasks | E11: Completed Tasks | F11: Completion Rate | H11: Category | I11: Total Tasks | J11: Completed | K11: Not Completed | M11: Priority | N11: Total Tasks | O11: Completed | P11: Not Completed | R11: Department | S11: Total Tasks | T11: Completed | U11: Not Completed | W11: Status | X11: Total Tasks | AB11: Date | AC11: Total Tasks | AD11: Completed Tasks | AE11: Completion Rate | AG11: Overdue Last Week | AH11: Ongoing This Week | AI11: Upcoming Next Week
C12: 1 | D12: =COUNTIFS('Tasks Board'!$L:$L, DATE($C$4, $C$9, $C12)) -> 0 | E12: =COUNTIFS('Tasks Board'!$L:$L, DATE($C$4, $C$9, $C12), 'Tasks Board'!$O:$O, "Completed") -> 0 | F12: =IF(D12=0, 0, E12/D12) -> 0 | H12: =IF(ISBLANK(Settings!D4),"",Settings!D4) -> Project | I12: =IF($H12 = "", "", COUNTIFS( 'Tasks Board'!$H:$H, $H12, 'Tasks Board'!$L:$L, ">="&DATE(Calculations!$C$4, Calculations!$C$9, 1), 'Tasks Board'!$L:$L, "<="&EOMONTH(DATE(Calculations!$C$4, Calculations!$C$9, 1), 0) )) -> 0 | J12: =IF($H12 = "", "", COUNTIFS( 'Tasks Board'!$H:$H, $H12, 'Tasks Board'!$L:$L, ">="&DATE(Calculations!$C$4, Calculations!$C$9, 1), 'Tasks Board'!$L:$L, "<="&EOMONTH(DATE(Calculations!$C$4, Calculations!$C$9, 1), 0), 'Tasks Board'!$O:$O, "Completed" )) -> 0 | K12: =I12-J12 -> 0 | M12: =IF(ISBLANK(Settings!L4),"",Settings!L4) -> Low | N12: =IF($M12 = "", "", COUNTIFS( 'Tasks Board'!$I:$I, $M12, 'Tasks Board'!$L:$L, ">="&DATE(Calculations!$C$4, Calculations!$C$9, 1), 'Tasks Board'!$L:$L, "<="&EOMONTH(DATE(Calculations!$C$4, Calculations!$C$9, 1), 0) )) -> 0 | O12: =IF($M12 = "", "", COUNTIFS( 'Tasks Board'!$I:$I, $M12, 'Tasks Board'!$L:$L, ">="&DATE(Calculations!$C$4, Calculations!$C$9, 1), 'Tasks Board'!$L:$L, "<="&EOMONTH(DATE(Calculations!$C$4, Calculations!$C$9, 1), 0), 'Tasks Board'!$O:$O, "Completed" )) -> 0 | P12: =N12-O12 -> 0 | R12: =IF(ISBLANK(Settings!G4), "", Settings!G4) -> Admin | S12: =IF($R12 = "", "", COUNTIFS( 'Tasks Board'!$J:$J, $R12, 'Tasks Board'!$L:$L, ">="&DATE(Calculations!$C$4, Calculations!$C$9, 1), 'Tasks Board'!$L:$L, "<="&EOMONTH(DATE(Calculations!$C$4, Calculations!$C$9, 1), 0) )) -> 0 | T12: =IF($R12 = "", "", COUNTIFS( 'Tasks Board'!$J:$J, $R12, 'Tasks Board'!$L:$L, ">="&DATE(Calculations!$C$4, Calculations!$C$9, 1), 'Tasks Board'!$L:$L, "<="&EOMONTH(DATE(Calculations!$C$4, Calculations!$C$9, 1), 0), 'Tasks Board'!$O:$O, "Completed" )) -> 0 | U12: =S12-T12 -> 0 | W12: =IF(ISBLANK(Settings!J4), "", Settings!J4) -> Not Started | X12: =COUNTIFS( 'Tasks Board'!$O:$O, $W12, 'Tasks Board'!$L:$L, ">="&DATE(Calculations!$C$4, Calculations!$C$9, 1), 'Tasks Board'!$L:$L, "<="&EOMONTH(DATE(Calculations!$C$4, Calculations!$C$9, 1), 0) ) -> 0 | AB12: =TODAY()-ROW(A1)+1 -> 46232 | AC12: =COUNTIF('Tasks Board'!$L:$L, AB12) -> 0 | AD12: =COUNTIFS('Tasks Board'!$L:$L, AB12, 'Tasks Board'!$O:$O, "Completed") -> 0 | AE12: =IF(AC12=0, 0, AD12/AC12) -> 0 | AG12: =TEXT(COUNTIFS( 'Tasks Board'!$L:$L, ">="&TODAY()-WEEKDAY(TODAY(), 2)-6, 'Tasks Board'!$L:$L, "<="&TODAY()-WEEKDAY(TODAY(), 2), 'Tasks Board'!$O:$O, "<>Completed", 'Tasks Board'!$P:$P, "<>Closed" ), "00") -> 00 | AH12: =TEXT( COUNTIFS( 'Tasks Board'!$L:$L, ">=" & (TODAY() - WEEKDAY(TODAY(), 2) + 1), 'Tasks Board'!$L:$L, "<=" & (TODAY() - WEEKDAY(TODAY(), 2) + 7), 'Tasks Board'!$O:$O, "<>Completed", 'Tasks Board'!$P:$P, "<>Closed" ), "00" ) -> 00 | AI12: =TEXT( COUNTIFS( 'Tasks Board'!$L:$L, ">=" & (TODAY() + 8 - WEEKDAY(TODAY(), 2)), 'Tasks Board'!$L:$L, "<=" & (TODAY() + 14 - WEEKDAY(TODAY(), 2)), 'Tasks Board'!$O:$O, "<>Completed", 'Tasks Board'!$P:$P, "<>Closed" ), "00" ) -> 00
C13: 2 | D13: =COUNTIFS('Tasks Board'!$L:$L, DATE($C$4, $C$9, $C13)) -> 0 | E13: =COUNTIFS('Tasks Board'!$L:$L, DATE($C$4, $C$9, $C13), 'Tasks Board'!$O:$O, "Completed") -> 0 | F13: =IF(D13=0, 0, E13/D13) -> 0 | H13: =IF(ISBLANK(Settings!D5),"",Settings!D5) -> Design | I13: =IF($H13 = "", "", COUNTIFS( 'Tasks Board'!$H:$H, $H13, 'Tasks Board'!$L:$L, ">="&DATE(Calculations!$C$4, Calculations!$C$9, 1), 'Tasks Board'!$L:$L, "<="&EOMONTH(DATE(Calculations!$C$4, Calculations!$C$9, 1), 0) )) -> 0 | J13: =IF($H13 = "", "", COUNTIFS( 'Tasks Board'!$H:$H, $H13, 'Tasks Board'!$L:$L, ">="&DATE(Calculations!$C$4, Calculations!$C$9, 1), 'Tasks Board'!$L:$L, "<="&EOMONTH(DATE(Calculations!$C$4, Calculations!$C$9, 1), 0), 'Tasks Board'!$O:$O, "Completed" )) -> 0 | K13: =I13-J13 -> 0 | M13: =IF(ISBLANK(Settings!L5),"",Settings!L5) -> Medium | N13: =IF($M13 = "", "", COUNTIFS( 'Tasks Board'!$I:$I, $M13, 'Tasks Board'!$L:$L, ">="&DATE(Calculations!$C$4, Calculations!$C$9, 1), 'Tasks Board'!$L:$L, "<="&EOMONTH(DATE(Calculations!$C$4, Calculations!$C$9, 1), 0) )) -> 0 | O13: =IF($M13 = "", "", COUNTIFS( 'Tasks Board'!$I:$I, $M13, 'Tasks Board'!$L:$L, ">="&DATE(Calculations!$C$4, Calculations!$C$9, 1), 'Tasks Board'!$L:$L, "<="&EOMONTH(DATE(Calculations!$C$4, Calculations!$C$9, 1), 0), 'Tasks Board'!$O:$O, "Completed" )) -> 0 | P13: =N13-O13 -> 0 | R13: =IF(ISBLANK(Settings!G5), "", Settings!G5) -> Production | S13: =IF($R13 = "", "", COUNTIFS( 'Tasks Board'!$J:$J, $R13, 'Tasks Board'!$L:$L, ">="&DATE(Calculations!$C$4, Calculations!$C$9, 1), 'Tasks Board'!$L:$L, "<="&EOMONTH(DATE(Calculations!$C$4, Calculations!$C$9, 1), 0) )) -> 0 | T13: =IF($R13 = "", "", COUNTIFS( 'Tasks Board'!$J:$J, $R13, 'Tasks Board'!$L:$L, ">="&DATE(Calculations!$C$4, Calculations!$C$9, 1), 'Tasks Board'!$L:$L, "<="&EOMONTH(DATE(Calculations!$C$4, Calculations!$C$9, 1), 0), 'Tasks Board'!$O:$O, "Completed" )) -> 0 | U13: =S13-T13 -> 0 | W13: =IF(ISBLANK(Settings!J5), "", Settings!J5) -> In Progress | X13: =COUNTIFS( 'Tasks Board'!$O:$O, $W13, 'Tasks Board'!$L:$L, ">="&DATE(Calculations!$C$4, Calculations!$C$9, 1), 'Tasks Board'!$L:$L, "<="&EOMONTH(DATE(Calculations!$C$4, Calculations!$C$9, 1), 0) ) -> 0 | AB13: =TODAY()-ROW(A2)+1 -> 46231 | AC13: =COUNTIF('Tasks Board'!$L:$L, AB13) -> 0 | AD13: =COUNTIFS('Tasks Board'!$L:$L, AB13, 'Tasks Board'!$O:$O, "Completed") -> 0 | AE13: =IF(AC13=0, 0, AD13/AC13) -> 0 | AG13: =TODAY() - WEEKDAY(TODAY(), 2) -6 -> 46223 | AH13: =TODAY() - WEEKDAY(TODAY(), 2) + 1 -> 46230 | AI13: =TODAY() - WEEKDAY(TODAY(), 2) + 8 -> 46237
C14: 3 | D14: =COUNTIFS('Tasks Board'!$L:$L, DATE($C$4, $C$9, $C14)) -> 0 | E14: =COUNTIFS('Tasks Board'!$L:$L, DATE($C$4, $C$9, $C14), 'Tasks Board'!$O:$O, "Completed") -> 0 | F14: =IF(D14=0, 0, E14/D14) -> 0 | H14: =IF(ISBLANK(Settings!D6),"",Settings!D6) -> Meeting | I14: =IF($H14 = "", "", COUNTIFS( 'Tasks Board'!$H:$H, $H14, 'Tasks Board'!$L:$L, ">="&DATE(Calculations!$C$4, Calculations!$C$9, 1), 'Tasks Board'!$L:$L, "<="&EOMONTH(DATE(Calculations!$C$4, Calculations!$C$9, 1), 0) )) -> 0 | J14: =IF($H14 = "", "", COUNTIFS( 'Tasks Board'!$H:$H, $H14, 'Tasks Board'!$L:$L, ">="&DATE(Calculations!$C$4, Calculations!$C$9, 1), 'Tasks Board'!$L:$L, "<="&EOMONTH(DATE(Calculations!$C$4, Calculations!$C$9, 1), 0), 'Tasks Board'!$O:$O, "Completed" )) -> 0 | K14: =I14-J14 -> 0 | M14: =IF(ISBLANK(Settings!L6),"",Settings!L6) -> High | N14: =IF($M14 = "", "", COUNTIFS( 'Tasks Board'!$I:$I, $M14, 'Tasks Board'!$L:$L, ">="&DATE(Calculations!$C$4, Calculations!$C$9, 1), 'Tasks Board'!$L:$L, "<="&EOMONTH(DATE(Calculations!$C$4, Calculations!$C$9, 1), 0) )) -> 0 | O14: =IF($M14 = "", "", COUNTIFS( 'Tasks Board'!$I:$I, $M14, 'Tasks Board'!$L:$L, ">="&DATE(Calculations!$C$4, Calculations!$C$9, 1), 'Tasks Board'!$L:$L, "<="&EOMONTH(DATE(Calculations!$C$4, Calculations!$C$9, 1), 0), 'Tasks Board'!$O:$O, "Completed" )) -> 0 | P14: =N14-O14 -> 0 | R14: =IF(ISBLANK(Settings!G6), "", Settings!G6) -> Marketing | S14: =IF($R14 = "", "", COUNTIFS( 'Tasks Board'!$J:$J, $R14, 'Tasks Board'!$L:$L, ">="&DATE(Calculations!$C$4, Calculations!$C$9, 1), 'Tasks Board'!$L:$L, "<="&EOMONTH(DATE(Calculations!$C$4, Calculations!$C$9, 1), 0) )) -> 0 | T14: =IF($R14 = "", "", COUNTIFS( 'Tasks Board'!$J:$J, $R14, 'Tasks Board'!$L:$L, ">="&DATE(Calculations!$C$4, Calculations!$C$9, 1), 'Tasks Board'!$L:$L, "<="&EOMONTH(DATE(Calculations!$C$4, Calculations!$C$9, 1), 0), 'Tasks Board'!$O:$O, "Completed" )) -> 0 | U14: =S14-T14 -> 0 | W14: =IF(ISBLANK(Settings!J6), "", Settings!J6) -> On Hold | X14: =COUNTIFS( 'Tasks Board'!$O:$O, $W14, 'Tasks Board'!$L:$L, ">="&DATE(Calculations!$C$4, Calculations!$C$9, 1), 'Tasks Board'!$L:$L, "<="&EOMONTH(DATE(Calculations!$C$4, Calculations!$C$9, 1), 0) ) -> 0 | AB14: =TODAY()-ROW(A3)+1 -> 46230 | AC14: =COUNTIF('Tasks Board'!$L:$L, AB14) -> 0 | AD14: =COUNTIFS('Tasks Board'!$L:$L, AB14, 'Tasks Board'!$O:$O, "Completed") -> 0 | AE14: =IF(AC14=0, 0, AD14/AC14) -> 0 | AG14: =TODAY() - WEEKDAY(TODAY(), 2) -> 46229 | AH14: =TODAY() - WEEKDAY(TODAY(), 2) + 7 -> 46236 | AI14: =TODAY() - WEEKDAY(TODAY(), 2) + 14 -> 46243
C15: 4 | D15: =COUNTIFS('Tasks Board'!$L:$L, DATE($C$4, $C$9, $C15)) -> 0 | E15: =COUNTIFS('Tasks Board'!$L:$L, DATE($C$4, $C$9, $C15), 'Tasks Board'!$O:$O, "Completed") -> 0 | F15: =IF(D15=0, 0, E15/D15) -> 0 | H15: =IF(ISBLANK(Settings!D7),"",Settings!D7) -> Development | I15: =IF($H15 = "", "", COUNTIFS( 'Tasks Board'!$H:$H, $H15, 'Tasks Board'!$L:$L, ">="&DATE(Calculations!$C$4, Calculations!$C$9, 1), 'Tasks Board'!$L:$L, "<="&EOMONTH(DATE(Calculations!$C$4, Calculations!$C$9, 1), 0) )) -> 0 | J15: =IF($H15 = "", "", COUNTIFS( 'Tasks Board'!$H:$H, $H15, 'Tasks Board'!$L:$L, ">="&DATE(Calculations!$C$4, Calculations!$C$9, 1), 'Tasks Board'!$L:$L, "<="&EOMONTH(DATE(Calculations!$C$4, Calculations!$C$9, 1), 0), 'Tasks Board'!$O:$O, "Completed" )) -> 0 | K15: =I15-J15 -> 0 | M15: =IF(ISBLANK(Settings!L7),"",Settings!L7) -> Very High | N15: =IF($M15 = "", "", COUNTIFS( 'Tasks Board'!$I:$I, $M15, 'Tasks Board'!$L:$L, ">="&DATE(Calculations!$C$4, Calculations!$C$9, 1), 'Tasks Board'!$L:$L, "<="&EOMONTH(DATE(Calculations!$C$4, Calculations!$C$9, 1), 0) )) -> 0 | O15: =IF($M15 = "", "", COUNTIFS( 'Tasks Board'!$I:$I, $M15, 'Tasks Board'!$L:$L, ">="&DATE(Calculations!$C$4, Calculations!$C$9, 1), 'Tasks Board'!$L:$L, "<="&EOMONTH(DATE(Calculations!$C$4, Calculations!$C$9, 1), 0), 'Tasks Board'!$O:$O, "Completed" )) -> 0 | P15: =N15-O15 -> 0 | R15: =IF(ISBLANK(Settings!G7), "", Settings!G7) -> Operations | S15: =IF($R15 = "", "", COUNTIFS( 'Tasks Board'!$J:$J, $R15, 'Tasks Board'!$L:$L, ">="&DATE(Calculations!$C$4, Calculations!$C$9, 1), 'Tasks Board'!$L:$L, "<="&EOMONTH(DATE(Calculations!$C$4, Calculations!$C$9, 1), 0) )) -> 0 | T15: =IF($R15 = "", "", COUNTIFS( 'Tasks Board'!$J:$J, $R15, 'Tasks Board'!$L:$L, ">="&DATE(Calculations!$C$4, Calculations!$C$9, 1), 'Tasks Board'!$L:$L, "<="&EOMONTH(DATE(Calculations!$C$4, Calculations!$C$9, 1), 0), 'Tasks Board'!$O:$O, "Completed" )) -> 0 | U15: =S15-T15 -> 0 | W15: =IF(ISBLANK(Settings!J7), "", Settings!J7) -> Active | X15: =COUNTIFS( 'Tasks Board'!$O:$O, $W15, 'Tasks Board'!$L:$L, ">="&DATE(Calculations!$C$4, Calculations!$C$9, 1), 'Tasks Board'!$L:$L, "<="&EOMONTH(DATE(Calculations!$C$4, Calculations!$C$9, 1), 0) ) -> 0 | AB15: =TODAY()-ROW(A4)+1 -> 46229 | AC15: =COUNTIF('Tasks Board'!$L:$L, AB15) -> 0 | AD15: =COUNTIFS('Tasks Board'!$L:$L, AB15, 'Tasks Board'!$O:$O, "Completed") -> 0 | AE15: =IF(AC15=0, 0, AD15/AC15) -> 0
C16: 5 | D16: =COUNTIFS('Tasks Board'!$L:$L, DATE($C$4, $C$9, $C16)) -> 0 | E16: =COUNTIFS('Tasks Board'!$L:$L, DATE($C$4, $C$9, $C16), 'Tasks Board'!$O:$O, "Completed") -> 0 | F16: =IF(D16=0, 0, E16/D16) -> 0 | H16: =IF(ISBLANK(Settings!D8),"",Settings!D8) -> Client Work | I16: =IF($H16 = "", "", COUNTIFS( 'Tasks Board'!$H:$H, $H16, 'Tasks Board'!$L:$L, ">="&DATE(Calculations!$C$4, Calculations!$C$9, 1), 'Tasks Board'!$L:$L, "<="&EOMONTH(DATE(Calculations!$C$4, Calculations!$C$9, 1), 0) )) -> 0 | J16: =IF($H16 = "", "", COUNTIFS( 'Tasks Board'!$H:$H, $H16, 'Tasks Board'!$L:$L, ">="&DATE(Calculations!$C$4, Calculations!$C$9, 1), 'Tasks Board'!$L:$L, "<="&EOMONTH(DATE(Calculations!$C$4, Calculations!$C$9, 1), 0), 'Tasks Board'!$O:$O, "Completed" )) -> 0 | K16: =I16-J16 -> 0 | M16: =IF(ISBLANK(Settings!L8),"",Settings!L8) -> Critical | N16: =IF($M16 = "", "", COUNTIFS( 'Tasks Board'!$I:$I, $M16, 'Tasks Board'!$L:$L, ">="&DATE(Calculations!$C$4, Calculations!$C$9, 1), 'Tasks Board'!$L:$L, "<="&EOMONTH(DATE(Calculations!$C$4, Calculations!$C$9, 1), 0) )) -> 0 | O16: =IF($M16 = "", "", COUNTIFS( 'Tasks Board'!$I:$I, $M16, 'Tasks Board'!$L:$L, ">="&DATE(Calculations!$C$4, Calculations!$C$9, 1), 'Tasks Board'!$L:$L, "<="&EOMONTH(DATE(Calculations!$C$4, Calculations!$C$9, 1), 0), 'Tasks Board'!$O:$O, "Completed" )) -> 0 | P16: =N16-O16 -> 0 | R16: =IF(ISBLANK(Settings!G8), "", Settings!G8) -> Finance | S16: =IF($R16 = "", "", COUNTIFS( 'Tasks Board'!$J:$J, $R16, 'Tasks Board'!$L:$L, ">="&DATE(Calculations!$C$4, Calculations!$C$9, 1), 'Tasks Board'!$L:$L, "<="&EOMONTH(DATE(Calculations!$C$4, Calculations!$C$9, 1), 0) )) -> 0 | T16: =IF($R16 = "", "", COUNTIFS( 'Tasks Board'!$J:$J, $R16, 'Tasks Board'!$L:$L, ">="&DATE(Calculations!$C$4, Calculations!$C$9, 1), 'Tasks Board'!$L:$L, "<="&EOMONTH(DATE(Calculations!$C$4, Calculations!$C$9, 1), 0), 'Tasks Board'!$O:$O, "Completed" )) -> 0 | U16: =S16-T16 -> 0 | W16: =IF(ISBLANK(Settings!J8), "", Settings!J8) -> In Review | X16: =COUNTIFS( 'Tasks Board'!$O:$O, $W16, 'Tasks Board'!$L:$L, ">="&DATE(Calculations!$C$4, Calculations!$C$9, 1), 'Tasks Board'!$L:$L, "<="&EOMONTH(DATE(Calculations!$C$4, Calculations!$C$9, 1), 0) ) -> 0 | AB16: =TODAY()-ROW(A5)+1 -> 46228 | AC16: =COUNTIF('Tasks Board'!$L:$L, AB16) -> 0 | AD16: =COUNTIFS('Tasks Board'!$L:$L, AB16, 'Tasks Board'!$O:$O, "Completed") -> 0 | AE16: =IF(AC16=0, 0, AD16/AC16) -> 0
C17: 6 | D17: =COUNTIFS('Tasks Board'!$L:$L, DATE($C$4, $C$9, $C17)) -> 0 | E17: =COUNTIFS('Tasks Board'!$L:$L, DATE($C$4, $C$9, $C17), 'Tasks Board'!$O:$O, "Completed") -> 0 | F17: =IF(D17=0, 0, E17/D17) -> 0 | H17: =IF(ISBLANK(Settings!D9),"",Settings!D9) -> Support | I17: =IF($H17 = "", "", COUNTIFS( 'Tasks Board'!$H:$H, $H17, 'Tasks Board'!$L:$L, ">="&DATE(Calculations!$C$4, Calculations!$C$9, 1), 'Tasks Board'!$L:$L, "<="&EOMONTH(DATE(Calculations!$C$4, Calculations!$C$9, 1), 0) )) -> 0 | J17: =IF($H17 = "", "", COUNTIFS( 'Tasks Board'!$H:$H, $H17, 'Tasks Board'!$L:$L, ">="&DATE(Calculations!$C$4, Calculations!$C$9, 1), 'Tasks Board'!$L:$L, "<="&EOMONTH(DATE(Calculations!$C$4, Calculations!$C$9, 1), 0), 'Tasks Board'!$O:$O, "Completed" )) -> 0 | K17: =I17-J17 -> 0 | M17: Total | N17: =SUM(N12:N16) -> 0 | O17: =SUM(O12:O16) -> 0 | P17: =SUM(P12:P16) -> 0 | R17: =IF(ISBLANK(Settings!G9), "", Settings!G9) | S17: =IF($R17 = "", "", COUNTIFS( 'Tasks Board'!$J:$J, $R17, 'Tasks Board'!$L:$L, ">="&DATE(Calculations!$C$4, Calculations!$C$9, 1), 'Tasks Board'!$L:$L, "<="&EOMONTH(DATE(Calculations!$C$4, Calculations!$C$9, 1), 0) )) | T17: =IF($R17 = "", "", COUNTIFS( 'Tasks Board'!$J:$J, $R17, 'Tasks Board'!$L:$L, ">="&DATE(Calculations!$C$4, Calculations!$C$9, 1), 'Tasks Board'!$L:$L, "<="&EOMONTH(DATE(Calculations!$C$4, Calculations!$C$9, 1), 0), 'Tasks Board'!$O:$O, "Completed" )) | U17: =S17-T17 -> #VALUE! | W17: =IF(ISBLANK(Settings!J9), "", Settings!J9) -> Completed | X17: =COUNTIFS( 'Tasks Board'!$O:$O, $W17, 'Tasks Board'!$L:$L, ">="&DATE(Calculations!$C$4, Calculations!$C$9, 1), 'Tasks Board'!$L:$L, "<="&EOMONTH(DATE(Calculations!$C$4, Calculations!$C$9, 1), 0) ) -> 0 | AB17: =TODAY()-ROW(A6)+1 -> 46227 | AC17: =COUNTIF('Tasks Board'!$L:$L, AB17) -> 0 | AD17: =COUNTIFS('Tasks Board'!$L:$L, AB17, 'Tasks Board'!$O:$O, "Completed") -> 0 | AE17: =IF(AC17=0, 0, AD17/AC17) -> 0
C18: 7 | D18: =COUNTIFS('Tasks Board'!$L:$L, DATE($C$4, $C$9, $C18)) -> 0 | E18: =COUNTIFS('Tasks Board'!$L:$L, DATE($C$4, $C$9, $C18), 'Tasks Board'!$O:$O, "Completed") -> 0 | F18: =IF(D18=0, 0, E18/D18) -> 0 | H18: =IF(ISBLANK(Settings!D10),"",Settings!D10) -> Training | I18: =IF($H18 = "", "", COUNTIFS( 'Tasks Board'!$H:$H, $H18, 'Tasks Board'!$L:$L, ">="&DATE(Calculations!$C$4, Calculations!$C$9, 1), 'Tasks Board'!$L:$L, "<="&EOMONTH(DATE(Calculations!$C$4, Calculations!$C$9, 1), 0) )) -> 0 | J18: =IF($H18 = "", "", COUNTIFS( 'Tasks Board'!$H:$H, $H18, 'Tasks Board'!$L:$L, ">="&DATE(Calculations!$C$4, Calculations!$C$9, 1), 'Tasks Board'!$L:$L, "<="&EOMONTH(DATE(Calculations!$C$4, Calculations!$C$9, 1), 0), 'Tasks Board'!$O:$O, "Completed" )) -> 0 | K18: =I18-J18 -> 0 | R18: =IF(ISBLANK(Settings!G10), "", Settings!G10) | S18: =IF($R18 = "", "", COUNTIFS( 'Tasks Board'!$J:$J, $R18, 'Tasks Board'!$L:$L, ">="&DATE(Calculations!$C$4, Calculations!$C$9, 1), 'Tasks Board'!$L:$L, "<="&EOMONTH(DATE(Calculations!$C$4, Calculations!$C$9, 1), 0) )) | T18: =IF($R18 = "", "", COUNTIFS( 'Tasks Board'!$J:$J, $R18, 'Tasks Board'!$L:$L, ">="&DATE(Calculations!$C$4, Calculations!$C$9, 1), 'Tasks Board'!$L:$L, "<="&EOMONTH(DATE(Calculations!$C$4, Calculations!$C$9, 1), 0), 'Tasks Board'!$O:$O, "Completed" )) | U18: =S18-T18 -> #VALUE! | W18: =IF(ISBLANK(Settings!J10), "", Settings!J10) -> Overdue | X18: =COUNTIFS( 'Tasks Board'!$O:$O, $W18, 'Tasks Board'!$L:$L, ">="&DATE(Calculations!$C$4, Calculations!$C$9, 1), 'Tasks Board'!$L:$L, "<="&EOMONTH(DATE(Calculations!$C$4, Calculations!$C$9, 1), 0) ) -> 0 | AB18: =TODAY()-ROW(A7)+1 -> 46226 | AC18: =COUNTIF('Tasks Board'!$L:$L, AB18) -> 0 | AD18: =COUNTIFS('Tasks Board'!$L:$L, AB18, 'Tasks Board'!$O:$O, "Completed") -> 0 | AE18: =IF(AC18=0, 0, AD18/AC18) -> 0
C19: 8 | D19: =COUNTIFS('Tasks Board'!$L:$L, DATE($C$4, $C$9, $C19)) -> 0 | E19: =COUNTIFS('Tasks Board'!$L:$L, DATE($C$4, $C$9, $C19), 'Tasks Board'!$O:$O, "Completed") -> 0 | F19: =IF(D19=0, 0, E19/D19) -> 0 | H19: =IF(ISBLANK(Settings!D11),"",Settings!D11) -> Quality Control | I19: =IF($H19 = "", "", COUNTIFS( 'Tasks Board'!$H:$H, $H19, 'Tasks Board'!$L:$L, ">="&DATE(Calculations!$C$4, Calculations!$C$9, 1), 'Tasks Board'!$L:$L, "<="&EOMONTH(DATE(Calculations!$C$4, Calculations!$C$9, 1), 0) )) -> 0 | J19: =IF($H19 = "", "", COUNTIFS( 'Tasks Board'!$H:$H, $H19, 'Tasks Board'!$L:$L, ">="&DATE(Calculations!$C$4, Calculations!$C$9, 1), 'Tasks Board'!$L:$L, "<="&EOMONTH(DATE(Calculations!$C$4, Calculations!$C$9, 1), 0), 'Tasks Board'!$O:$O, "Completed" )) -> 0 | K19: =I19-J19 -> 0 | R19: =IF(ISBLANK(Settings!G11), "", Settings!G11) | S19: =IF($R19 = "", "", COUNTIFS( 'Tasks Board'!$J:$J, $R19, 'Tasks Board'!$L:$L, ">="&DATE(Calculations!$C$4, Calculations!$C$9, 1), 'Tasks Board'!$L:$L, "<="&EOMONTH(DATE(Calculations!$C$4, Calculations!$C$9, 1), 0) )) | T19: =IF($R19 = "", "", COUNTIFS( 'Tasks Board'!$J:$J, $R19, 'Tasks Board'!$L:$L, ">="&DATE(Calculations!$C$4, Calculations!$C$9, 1), 'Tasks Board'!$L:$L, "<="&EOMONTH(DATE(Calculations!$C$4, Calculations!$C$9, 1), 0), 'Tasks Board'!$O:$O, "Completed" )) | U19: =S19-T19 -> #VALUE! | W19: =IF(ISBLANK(Settings!J11), "", Settings!J11) -> Cancelled | X19: =COUNTIFS( 'Tasks Board'!$O:$O, $W19, 'Tasks Board'!$L:$L, ">="&DATE(Calculations!$C$4, Calculations!$C$9, 1), 'Tasks Board'!$L:$L, "<="&EOMONTH(DATE(Calculations!$C$4, Calculations!$C$9, 1), 0) ) -> 0 | AC19: =SUM(AC12:AC18) -> 0 | AD19: =SUM(AD12:AD18) -> 0 | AE19: =AD19/AC19 -> #DIV/0!
C20: 9 | D20: =COUNTIFS('Tasks Board'!$L:$L, DATE($C$4, $C$9, $C20)) -> 0 | E20: =COUNTIFS('Tasks Board'!$L:$L, DATE($C$4, $C$9, $C20), 'Tasks Board'!$O:$O, "Completed") -> 0 | F20: =IF(D20=0, 0, E20/D20) -> 0 | H20: =IF(ISBLANK(Settings!D12),"",Settings!D12) -> Research | I20: =IF($H20 = "", "", COUNTIFS( 'Tasks Board'!$H:$H, $H20, 'Tasks Board'!$L:$L, ">="&DATE(Calculations!$C$4, Calculations!$C$9, 1), 'Tasks Board'!$L:$L, "<="&EOMONTH(DATE(Calculations!$C$4, Calculations!$C$9, 1), 0) )) -> 0 | J20: =IF($H20 = "", "", COUNTIFS( 'Tasks Board'!$H:$H, $H20, 'Tasks Board'!$L:$L, ">="&DATE(Calculations!$C$4, Calculations!$C$9, 1), 'Tasks Board'!$L:$L, "<="&EOMONTH(DATE(Calculations!$C$4, Calculations!$C$9, 1), 0), 'Tasks Board'!$O:$O, "Completed" )) -> 0 | K20: =I20-J20 -> 0 | R20: =IF(ISBLANK(Settings!G12), "", Settings!G12) | S20: =IF($R20 = "", "", COUNTIFS( 'Tasks Board'!$J:$J, $R20, 'Tasks Board'!$L:$L, ">="&DATE(Calculations!$C$4, Calculations!$C$9, 1), 'Tasks Board'!$L:$L, "<="&EOMONTH(DATE(Calculations!$C$4, Calculations!$C$9, 1), 0) )) | T20: =IF($R20 = "", "", COUNTIFS( 'Tasks Board'!$J:$J, $R20, 'Tasks Board'!$L:$L, ">="&DATE(Calculations!$C$4, Calculations!$C$9, 1), 'Tasks Board'!$L:$L, "<="&EOMONTH(DATE(Calculations!$C$4, Calculations!$C$9, 1), 0), 'Tasks Board'!$O:$O, "Completed" )) | U20: =S20-T20 -> #VALUE! | W20: =IF(ISBLANK(Settings!J12), "", Settings!J12) | X20: =COUNTIFS( 'Tasks Board'!$O:$O, $W20, 'Tasks Board'!$L:$L, ">="&DATE(Calculations!$C$4, Calculations!$C$9, 1), 'Tasks Board'!$L:$L, "<="&EOMONTH(DATE(Calculations!$C$4, Calculations!$C$9, 1), 0) ) -> 0 | AE20: =100%-AE19 -> #DIV/0!
C21: 10 | D21: =COUNTIFS('Tasks Board'!$L:$L, DATE($C$4, $C$9, $C21)) -> 0 | E21: =COUNTIFS('Tasks Board'!$L:$L, DATE($C$4, $C$9, $C21), 'Tasks Board'!$O:$O, "Completed") -> 0 | F21: =IF(D21=0, 0, E21/D21) -> 0 | H21: =IF(ISBLANK(Settings!D13),"",Settings!D13) -> Sales | I21: =IF($H21 = "", "", COUNTIFS( 'Tasks Board'!$H:$H, $H21, 'Tasks Board'!$L:$L, ">="&DATE(Calculations!$C$4, Calculations!$C$9, 1), 'Tasks Board'!$L:$L, "<="&EOMONTH(DATE(Calculations!$C$4, Calculations!$C$9, 1), 0) )) -> 0 | J21: =IF($H21 = "", "", COUNTIFS( 'Tasks Board'!$H:$H, $H21, 'Tasks Board'!$L:$L, ">="&DATE(Calculations!$C$4, Calculations!$C$9, 1), 'Tasks Board'!$L:$L, "<="&EOMONTH(DATE(Calculations!$C$4, Calculations!$C$9, 1), 0), 'Tasks Board'!$O:$O, "Completed" )) -> 0 | K21: =I21-J21 -> 0 | R21: =IF(ISBLANK(Settings!G13), "", Settings!G13) | S21: =IF($R21 = "", "", COUNTIFS( 'Tasks Board'!$J:$J, $R21, 'Tasks Board'!$L:$L, ">="&DATE(Calculations!$C$4, Calculations!$C$9, 1), 'Tasks Board'!$L:$L, "<="&EOMONTH(DATE(Calculations!$C$4, Calculations!$C$9, 1), 0) )) | T21: =IF($R21 = "", "", COUNTIFS( 'Tasks Board'!$J:$J, $R21, 'Tasks Board'!$L:$L, ">="&DATE(Calculations!$C$4, Calculations!$C$9, 1), 'Tasks Board'!$L:$L, "<="&EOMONTH(DATE(Calculations!$C$4, Calculations!$C$9, 1), 0), 'Tasks Board'!$O:$O, "Completed" )) | U21: =S21-T21 -> #VALUE! | W21: =IF(ISBLANK(Settings!J13), "", Settings!J13) | X21: =COUNTIFS( 'Tasks Board'!$O:$O, $W21, 'Tasks Board'!$L:$L, ">="&DATE(Calculations!$C$4, Calculations!$C$9, 1), 'Tasks Board'!$L:$L, "<="&EOMONTH(DATE(Calculations!$C$4, Calculations!$C$9, 1), 0) ) -> 0 | AE21: Not Completed
C22: 11 | D22: =COUNTIFS('Tasks Board'!$L:$L, DATE($C$4, $C$9, $C22)) -> 0 | E22: =COUNTIFS('Tasks Board'!$L:$L, DATE($C$4, $C$9, $C22), 'Tasks Board'!$O:$O, "Completed") -> 0 | F22: =IF(D22=0, 0, E22/D22) -> 0 | H22: Total | I22: =SUM(I12:I21) -> 0 | J22: =SUM(J12:J21) -> 0 | K22: =SUM(K12:K21) -> 0 | R22: Total | S22: =SUM(S12:S21) -> 0 | T22: =SUM(T12:T21) -> 0 | U22: =SUM(U12:U21) -> #VALUE! | W22: Total | X22: =SUM(X12:X21) -> 0
C23: 12 | D23: =COUNTIFS('Tasks Board'!$L:$L, DATE($C$4, $C$9, $C23)) -> 0 | E23: =COUNTIFS('Tasks Board'!$L:$L, DATE($C$4, $C$9, $C23), 'Tasks Board'!$O:$O, "Completed") -> 0 | F23: =IF(D23=0, 0, E23/D23) -> 0
C24: 13 | D24: =COUNTIFS('Tasks Board'!$L:$L, DATE($C$4, $C$9, $C24)) -> 0 | E24: =COUNTIFS('Tasks Board'!$L:$L, DATE($C$4, $C$9, $C24), 'Tasks Board'!$O:$O, "Completed") -> 0 | F24: =IF(D24=0, 0, E24/D24) -> 0
C25: 14 | D25: =COUNTIFS('Tasks Board'!$L:$L, DATE($C$4, $C$9, $C25)) -> 0 | E25: =COUNTIFS('Tasks Board'!$L:$L, DATE($C$4, $C$9, $C25), 'Tasks Board'!$O:$O, "Completed") -> 0 | F25: =IF(D25=0, 0, E25/D25) -> 0
C26: 15 | D26: =COUNTIFS('Tasks Board'!$L:$L, DATE($C$4, $C$9, $C26)) -> 0 | E26: =COUNTIFS('Tasks Board'!$L:$L, DATE($C$4, $C$9, $C26), 'Tasks Board'!$O:$O, "Completed") -> 0 | F26: =IF(D26=0, 0, E26/D26) -> 0
C27: 16 | D27: =COUNTIFS('Tasks Board'!$L:$L, DATE($C$4, $C$9, $C27)) -> 0 | E27: =COUNTIFS('Tasks Board'!$L:$L, DATE($C$4, $C$9, $C27), 'Tasks Board'!$O:$O, "Completed") -> 0 | F27: =IF(D27=0, 0, E27/D27) -> 0
C28: 17 | D28: =COUNTIFS('Tasks Board'!$L:$L, DATE($C$4, $C$9, $C28)) -> 0 | E28: =COUNTIFS('Tasks Board'!$L:$L, DATE($C$4, $C$9, $C28), 'Tasks Board'!$O:$O, "Completed") -> 0 | F28: =IF(D28=0, 0, E28/D28) -> 0
C29: 18 | D29: =COUNTIFS('Tasks Board'!$L:$L, DATE($C$4, $C$9, $C29)) -> 0 | E29: =COUNTIFS('Tasks Board'!$L:$L, DATE($C$4, $C$9, $C29), 'Tasks Board'!$O:$O, "Completed") -> 0 | F29: =IF(D29=0, 0, E29/D29) -> 0
C30: 19 | D30: =COUNTIFS('Tasks Board'!$L:$L, DATE($C$4, $C$9, $C30)) -> 0 | E30: =COUNTIFS('Tasks Board'!$L:$L, DATE($C$4, $C$9, $C30), 'Tasks Board'!$O:$O, "Completed") -> 0 | F30: =IF(D30=0, 0, E30/D30) -> 0
C31: 20 | D31: =COUNTIFS('Tasks Board'!$L:$L, DATE($C$4, $C$9, $C31)) -> 0 | E31: =COUNTIFS('Tasks Board'!$L:$L, DATE($C$4, $C$9, $C31), 'Tasks Board'!$O:$O, "Completed") -> 0 | F31: =IF(D31=0, 0, E31/D31) -> 0
C32: 21 | D32: =COUNTIFS('Tasks Board'!$L:$L, DATE($C$4, $C$9, $C32)) -> 0 | E32: =COUNTIFS('Tasks Board'!$L:$L, DATE($C$4, $C$9, $C32), 'Tasks Board'!$O:$O, "Completed") -> 0 | F32: =IF(D32=0, 0, E32/D32) -> 0
C33: 22 | D33: =COUNTIFS('Tasks Board'!$L:$L, DATE($C$4, $C$9, $C33)) -> 0 | E33: =COUNTIFS('Tasks Board'!$L:$L, DATE($C$4, $C$9, $C33), 'Tasks Board'!$O:$O, "Completed") -> 0 | F33: =IF(D33=0, 0, E33/D33) -> 0
C34: 23 | D34: =COUNTIFS('Tasks Board'!$L:$L, DATE($C$4, $C$9, $C34)) -> 0 | E34: =COUNTIFS('Tasks Board'!$L:$L, DATE($C$4, $C$9, $C34), 'Tasks Board'!$O:$O, "Completed") -> 0 | F34: =IF(D34=0, 0, E34/D34) -> 0
... C42: 31 | D42: =COUNTIFS('Tasks Board'!$L:$L, DATE($C$4, $C$9, $C42)) -> 0 | E42: =COUNTIFS('Tasks Board'!$L:$L, DATE($C$4, $C$9, $C42), 'Tasks Board'!$O:$O, "Completed") -> 0 | F42: =IF(D42=0, 0, E42/D42) -> 0
C43: Total | D43: =SUM(D12:D42) -> 0 | E43: =SUM(E12:E42) -> 0 | F43: =AVERAGE(F12:F42) -> 0
C44: Peak | D44: =MAX(D12:D42) -> 0 | E44: =MAX(E12:E42) -> 0 | F44: =MAX(F12:F42) -> 0
C46: Yearly Performance Breakdown
C47: Month | D47: Total Tasks | E47: Completed Tasks | F47: Completion Rate
C48: January | D48: =IFERROR(COUNTIFS('Tasks Board'!$L:$L, ">="&DATE($C$4, MATCH($C48, {"January","February","March","April","May","June","July","August","September","October","November","December"}, 0), 1), 'Tasks Board'!$L:$L, "<="&EOMONTH(DATE($C$4, MATCH($C48, {"January","February","March","April","May","June","July","August","September","October","November","December"}, 0), 1), 0)), 0) -> 0 | E48: =IFERROR(COUNTIFS('Tasks Board'!$L:$L, ">="&DATE($C$4, MATCH($C48, {"January","February","March","April","May","June","July","August","September","October","November","December"}, 0), 1), 'Tasks Board'!$L:$L, "<="&EOMONTH(DATE($C$4, MATCH($C48, {"January","February","March","April","May","June","July","August","September","October","November","December"}, 0), 1), 0), 'Tasks Board'!$O:$O, "Completed"), 0) -> 0 | F48: =IF(D48=0, 0, E48/D48) -> 0
C49: February | D49: =IFERROR(COUNTIFS('Tasks Board'!$L:$L, ">="&DATE($C$4, MATCH($C49, {"January","February","March","April","May","June","July","August","September","October","November","December"}, 0), 1), 'Tasks Board'!$L:$L, "<="&EOMONTH(DATE($C$4, MATCH($C49, {"January","February","March","April","May","June","July","August","September","October","November","December"}, 0), 1), 0)), 0) -> 0 | E49: =IFERROR(COUNTIFS('Tasks Board'!$L:$L, ">="&DATE($C$4, MATCH($C49, {"January","February","March","April","May","June","July","August","September","October","November","December"}, 0), 1), 'Tasks Board'!$L:$L, "<="&EOMONTH(DATE($C$4, MATCH($C49, {"January","February","March","April","May","June","July","August","September","October","November","December"}, 0), 1), 0), 'Tasks Board'!$O:$O, "Completed"), 0) -> 0 | F49: =IF(D49=0, 0, E49/D49) -> 0
C50: March | D50: =IFERROR(COUNTIFS('Tasks Board'!$L:$L, ">="&DATE($C$4, MATCH($C50, {"January","February","March","April","May","June","July","August","September","October","November","December"}, 0), 1), 'Tasks Board'!$L:$L, "<="&EOMONTH(DATE($C$4, MATCH($C50, {"January","February","March","April","May","June","July","August","September","October","November","December"}, 0), 1), 0)), 0) -> 0 | E50: =IFERROR(COUNTIFS('Tasks Board'!$L:$L, ">="&DATE($C$4, MATCH($C50, {"January","February","March","April","May","June","July","August","September","October","November","December"}, 0), 1), 'Tasks Board'!$L:$L, "<="&EOMONTH(DATE($C$4, MATCH($C50, {"January","February","March","April","May","June","July","August","September","October","November","December"}, 0), 1), 0), 'Tasks Board'!$O:$O, "Completed"), 0) -> 0 | F50: =IF(D50=0, 0, E50/D50) -> 0
...

Sheet Advance Daily
C1: ADVANCE DAILY
C2: Reimagining Spreadsheets through Gamified, Science-based Productivity
C4: Team Task Management System
C5: 8-in-1 Tracker Bundle
C7: License Information: This Team Task Management System ("Tracker") is the intellectual property of Advance Daily. By acquiring, downloading, or using this Tracker, you agree to the terms and conditions of this license. License Grant: Advance Daily grants you a non-exclusive, non-transferable, revocable license to use the Tracker for personal or organizational productivity tracking purposes. This license does not grant you any rights to resell, sublicense, or distribute the Tracker. Intellectual Property Rights: The Tracker is protected by copyright and other intellectual property laws. Advance Daily retains all rights, title, and interest in and to the Tracker, including all copyrights, trademarks, and any other proprietary rights. Restrictions: You are expressly prohibited from reselling, sublicensing, or distributing, transferring the Tracker, in whole or in part, to any third party without the prior written consent of Advance Daily. Any unauthorized use or distribution constitutes a violation of intellectual property rights and will be subject to legal action.
E24: www.advance-daily.com | R24: facebook.com/AdvanceDailyInc
E26: admin@advance-daily.com | R26: @advance.daily
E27: All rights reserved. © Advance Daily 2024

Sheet Settings
C1: SETTINGS & CUSTOMIZATION
C3: Category | F3: Department | I3: Status | L3: Priority | N3: Remarks
C4: 1 | D4: Project | F4: 1 | G4: Admin | I4: 1 | J4: Not Started | L4: Low | N4: Open
C5: 2 | D5: Design | F5: 2 | G5: Production | I5: 2 | J5: In Progress | L5: Medium | N5: Closed
C6: 3 | D6: Meeting | F6: 3 | G6: Marketing | I6: 3 | J6: On Hold | L6: High
C7: 4 | D7: Development | F7: 4 | G7: Operations | I7: 4 | J7: Active | L7: Very High | N7: Status (Meeting Archive)
C8: 5 | D8: Client Work | F8: 5 | G8: Finance | I8: 5 | J8: In Review | L8: Critical | N8: Listed on Tasks Board
C9: 6 | D9: Support | F9: 6 | I9: 6 | J9: Completed | N9: Not Listed
C10: 7 | D10: Training | F10: 7 | I10: 7 | J10: Overdue
C11: 8 | D11: Quality Control | F11: 8 | I11: 8 | J11: Cancelled
C12: 9 | D12: Research | F12: 9 | I12: 9
C13: 10 | D13: Sales | F13: 10 | I13: 10

Sheet Dashboard
C2: TEAM TASK MANAGEMENT SYSTEM | Q2: January | T2: 2024

Sheet Tasks Board
C1: MAIN TASKS BOARD
C3: Date Today | F3: Tasks Due Today by Priority | K3: Tasks Due Today by Status | Q3: Distribution of Tasks by Category | X3: Selected Year (Select in Dashboard)
C4: =TODAY() -> 46232 | F4: =Settings!L8 -> Critical | G4: =COUNTIFS(L11:L1000, $C$4, I11:I1000, F4, P11:P1000, "Open") -> 0 | X4: =Dashboard!$T$2 -> 2024
C5: =C4 -> 46232 | F5: =Settings!L7 -> Very High | G5: =COUNTIFS(L11:L1000, $C$4, I11:I1000, F5, P11:P1000, "Open") -> 0
F6: =Settings!L6 -> High | G6: =COUNTIFS(L11:L1000, $C$4, I11:I1000, F6, P11:P1000, "Open") -> 0 | X6: Selected Month (Select in Dashboard)
C7: Tasks Due Today | F7: =Settings!L5 -> Medium | G7: =COUNTIFS(L11:L1000, $C$4, I11:I1000, F7, P11:P1000, "Open") -> 0 | X7: =Dashboard!$Q$2 -> January
C8: =SUM(G4:G8) -> 0 | F8: =Settings!L4 -> Low | G8: =COUNTIFS(L11:L1000, $C$4, I11:I1000, F8, P11:P1000, "Open") -> 0
X9: =MONTH(DATE(2023, MATCH(X7, {"January","February","March","April","May","June","July","August","September","October","November","December"}, 0), 1)) -> 1
C10: Person Assigned | D10: Task ID | E10: Task Description | H10: Category | I10: Priority | J10: Department | L10: Due Date | M10: Days Left | N10: Assigned On | O10: Status | P10: Remarks | R10: Attachments | S10: Notes | U10: Tasks Due Today by Status | X10: Monthly Performance Breakdown
M11: =IF(ISBLANK(L11), "", L11 - $C$4) | U11: Status | V11: Tasks Due Today | X11: Date | Y11: Total Tasks | Z11: Completed Tasks | AA11: Completion Rate
M12: =IF(ISBLANK(L12), "", L12 - $C$4) | U12: =IF(ISBLANK(Settings!J4), "", Settings!J4) -> Not Started | V12: =COUNTIFS(L:L, $C$4, O:O, U12, P:P, "Open") -> 0 | X12: 1 | Y12: =COUNTIFS($L:$L, DATE($X$4, $X$9, $X12)) -> 0 | Z12: =COUNTIFS($L:$L, DATE($X$4, $X$9, $X12), $O:$O, "Completed") -> 0 | AA12: =IF(Y12=0, 0, Z12/Y12) -> 0
M13: =IF(ISBLANK(L13), "", L13 - $C$4) | U13: =IF(ISBLANK(Settings!J5), "", Settings!J5) -> In Progress | V13: =COUNTIFS(L:L, $C$4, O:O, U13, P:P, "Open") -> 0 | X13: 2 | Y13: =COUNTIFS($L:$L, DATE($X$4, $X$9, $X13)) -> 0 | Z13: =COUNTIFS($L:$L, DATE($X$4, $X$9, $X13), $O:$O, "Completed") -> 0 | AA13: =IF(Y13=0, 0, Z13/Y13) -> 0
M14: =IF(ISBLANK(L14), "", L14 - $C$4) | U14: =IF(ISBLANK(Settings!J6), "", Settings!J6) -> On Hold | V14: =COUNTIFS(L:L, $C$4, O:O, U14, P:P, "Open") -> 0 | X14: 3 | Y14: =COUNTIFS($L:$L, DATE($X$4, $X$9, $X14)) -> 0 | Z14: =COUNTIFS($L:$L, DATE($X$4, $X$9, $X14), $O:$O, "Completed") -> 0 | AA14: =IF(Y14=0, 0, Z14/Y14) -> 0
M15: =IF(ISBLANK(L15), "", L15 - $C$4) | U15: =IF(ISBLANK(Settings!J7), "", Settings!J7) -> Active | V15: =COUNTIFS(L:L, $C$4, O:O, U15, P:P, "Open") -> 0 | X15: 4 | Y15: =COUNTIFS($L:$L, DATE($X$4, $X$9, $X15)) -> 0 | Z15: =COUNTIFS($L:$L, DATE($X$4, $X$9, $X15), $O:$O, "Completed") -> 0 | AA15: =IF(Y15=0, 0, Z15/Y15) -> 0
M16: =IF(ISBLANK(L16), "", L16 - $C$4) | U16: =IF(ISBLANK(Settings!J8), "", Settings!J8) -> In Review | V16: =COUNTIFS(L:L, $C$4, O:O, U16, P:P, "Open") -> 0 | X16: 5 | Y16: =COUNTIFS($L:$L, DATE($X$4, $X$9, $X16)) -> 0 | Z16: =COUNTIFS($L:$L, DATE($X$4, $X$9, $X16), $O:$O, "Completed") -> 0 | AA16: =IF(Y16=0, 0, Z16/Y16) -> 0
M17: =IF(ISBLANK(L17), "", L17 - $C$4) | U17: =IF(ISBLANK(Settings!J9), "", Settings!J9) -> Completed | V17: =COUNTIFS(L:L, $C$4, O:O, U17, P:P, "Open") -> 0 | X17: 6 | Y17: =COUNTIFS($L:$L, DATE($X$4, $X$9, $X17)) -> 0 | Z17: =COUNTIFS($L:$L, DATE($X$4, $X$9, $X17), $O:$O, "Completed") -> 0 | AA17: =IF(Y17=0, 0, Z17/Y17) -> 0
M18: =IF(ISBLANK(L18), "", L18 - $C$4) | U18: =IF(ISBLANK(Settings!J10), "", Settings!J10) -> Overdue | V18: =COUNTIFS(L:L, $C$4, O:O, U18, P:P, "Open") -> 0 | X18: 7 | Y18: =COUNTIFS($L:$L, DATE($X$4, $X$9, $X18)) -> 0 | Z18: =COUNTIFS($L:$L, DATE($X$4, $X$9, $X18), $O:$O, "Completed") -> 0 | AA18: =IF(Y18=0, 0, Z18/Y18) -> 0
M19: =IF(ISBLANK(L19), "", L19 - $C$4) | U19: =IF(ISBLANK(Settings!J11), "", Settings!J11) -> Cancelled | V19: =COUNTIFS(L:L, $C$4, O:O, U19, P:P, "Open") -> 0 | X19: 8 | Y19: =COUNTIFS($L:$L, DATE($X$4, $X$9, $X19)) -> 0 | Z19: =COUNTIFS($L:$L, DATE($X$4, $X$9, $X19), $O:$O, "Completed") -> 0 | AA19: =IF(Y19=0, 0, Z19/Y19) -> 0
M20: =IF(ISBLANK(L20), "", L20 - $C$4) | U20: =IF(ISBLANK(Settings!J12), "", Settings!J12) | V20: =COUNTIFS(L:L, $C$4, O:O, U20, P:P, "Open") -> 0 | X20: 9 | Y20: =COUNTIFS($L:$L, DATE($X$4, $X$9, $X20)) -> 0 | Z20: =COUNTIFS($L:$L, DATE($X$4, $X$9, $X20), $O:$O, "Completed") -> 0 | AA20: =IF(Y20=0, 0, Z20/Y20) -> 0
M21: =IF(ISBLANK(L21), "", L21 - $C$4) | U21: =IF(ISBLANK(Settings!J13), "", Settings!J13) | V21: =COUNTIFS(L:L, $C$4, O:O, U21, P:P, "Open") -> 0 | X21: 10 | Y21: =COUNTIFS($L:$L, DATE($X$4, $X$9, $X21)) -> 0 | Z21: =COUNTIFS($L:$L, DATE($X$4, $X$9, $X21), $O:$O, "Completed") -> 0 | AA21: =IF(Y21=0, 0, Z21/Y21) -> 0
M22: =IF(ISBLANK(L22), "", L22 - $C$4) | X22: 11 | Y22: =COUNTIFS($L:$L, DATE($X$4, $X$9, $X22)) -> 0 | Z22: =COUNTIFS($L:$L, DATE($X$4, $X$9, $X22), $O:$O, "Completed") -> 0 | AA22: =IF(Y22=0, 0, Z22/Y22) -> 0
M23: =IF(ISBLANK(L23), "", L23 - $C$4) | U23: Distribution of Tasks by Category | X23: 12 | Y23: =COUNTIFS($L:$L, DATE($X$4, $X$9, $X23)) -> 0 | Z23: =COUNTIFS($L:$L, DATE($X$4, $X$9, $X23), $O:$O, "Completed") -> 0 | AA23: =IF(Y23=0, 0, Z23/Y23) -> 0
M24: =IF(ISBLANK(L24), "", L24 - $C$4) | U24: Category | V24: Number of Tasks | X24: 13 | Y24: =COUNTIFS($L:$L, DATE($X$4, $X$9, $X24)) -> 0 | Z24: =COUNTIFS($L:$L, DATE($X$4, $X$9, $X24), $O:$O, "Completed") -> 0 | AA24: =IF(Y24=0, 0, Z24/Y24) -> 0
M25: =IF(ISBLANK(L25), "", L25 - $C$4) | U25: =IF(ISBLANK(Settings!D4),"",Settings!D4) -> Project | V25: =IF(OR(ISBLANK(U25), U25=""), "", COUNTIF('Tasks Board'!$H:$H, U25)) -> 0 | X25: 14 | Y25: =COUNTIFS($L:$L, DATE($X$4, $X$9, $X25)) -> 0 | Z25: =COUNTIFS($L:$L, DATE($X$4, $X$9, $X25), $O:$O, "Completed") -> 0 | AA25: =IF(Y25=0, 0, Z25/Y25) -> 0
M26: =IF(ISBLANK(L26), "", L26 - $C$4) | U26: =IF(ISBLANK(Settings!D5),"",Settings!D5) -> Design | V26: =IF(OR(ISBLANK(U26), U26=""), "", COUNTIF('Tasks Board'!$H:$H, U26)) -> 0 | X26: 15 | Y26: =COUNTIFS($L:$L, DATE($X$4, $X$9, $X26)) -> 0 | Z26: =COUNTIFS($L:$L, DATE($X$4, $X$9, $X26), $O:$O, "Completed") -> 0 | AA26: =IF(Y26=0, 0, Z26/Y26) -> 0
M27: =IF(ISBLANK(L27), "", L27 - $C$4) | U27: =IF(ISBLANK(Settings!D6),"",Settings!D6) -> Meeting | V27: =IF(OR(ISBLANK(U27), U27=""), "", COUNTIF('Tasks Board'!$H:$H, U27)) -> 0 | X27: 16 | Y27: =COUNTIFS($L:$L, DATE($X$4, $X$9, $X27)) -> 0 | Z27: =COUNTIFS($L:$L, DATE($X$4, $X$9, $X27), $O:$O, "Completed") -> 0 | AA27: =IF(Y27=0, 0, Z27/Y27) -> 0
M28: =IF(ISBLANK(L28), "", L28 - $C$4) | U28: =IF(ISBLANK(Settings!D7),"",Settings!D7) -> Development | V28: =IF(OR(ISBLANK(U28), U28=""), "", COUNTIF('Tasks Board'!$H:$H, U28)) -> 0 | X28: 17 | Y28: =COUNTIFS($L:$L, DATE($X$4, $X$9, $X28)) -> 0 | Z28: =COUNTIFS($L:$L, DATE($X$4, $X$9, $X28), $O:$O, "Completed") -> 0 | AA28: =IF(Y28=0, 0, Z28/Y28) -> 0
M29: =IF(ISBLANK(L29), "", L29 - $C$4) | U29: =IF(ISBLANK(Settings!D8),"",Settings!D8) -> Client Work | V29: =IF(OR(ISBLANK(U29), U29=""), "", COUNTIF('Tasks Board'!$H:$H, U29)) -> 0 | X29: 18 | Y29: =COUNTIFS($L:$L, DATE($X$4, $X$9, $X29)) -> 0 | Z29: =COUNTIFS($L:$L, DATE($X$4, $X$9, $X29), $O:$O, "Completed") -> 0 | AA29: =IF(Y29=0, 0, Z29/Y29) -> 0
M30: =IF(ISBLANK(L30), "", L30 - $C$4) | U30: =IF(ISBLANK(Settings!D9),"",Settings!D9) -> Support | V30: =IF(OR(ISBLANK(U30), U30=""), "", COUNTIF('Tasks Board'!$H:$H, U30)) -> 0 | X30: 19 | Y30: =COUNTIFS($L:$L, DATE($X$4, $X$9, $X30)) -> 0 | Z30: =COUNTIFS($L:$L, DATE($X$4, $X$9, $X30), $O:$O, "Completed") -> 0 | AA30: =IF(Y30=0, 0, Z30/Y30) -> 0
M31: =IF(ISBLANK(L31), "", L31 - $C$4) | U31: =IF(ISBLANK(Settings!D10),"",Settings!D10) -> Training | V31: =IF(OR(ISBLANK(U31), U31=""), "", COUNTIF('Tasks Board'!$H:$H, U31)) -> 0 | X31: 20 | Y31: =COUNTIFS($L:$L, DATE($X$4, $X$9, $X31)) -> 0 | Z31: =COUNTIFS($L:$L, DATE($X$4, $X$9, $X31), $O:$O, "Completed") -> 0 | AA31: =IF(Y31=0, 0, Z31/Y31) -> 0
M32: =IF(ISBLANK(L32), "", L32 - $C$4) | U32: =IF(ISBLANK(Settings!D11),"",Settings!D11) -> Quality Control | V32: =IF(OR(ISBLANK(U32), U32=""), "", COUNTIF('Tasks Board'!$H:$H, U32)) -> 0 | X32: 21 | Y32: =COUNTIFS($L:$L, DATE($X$4, $X$9, $X32)) -> 0 | Z32: =COUNTIFS($L:$L, DATE($X$4, $X$9, $X32), $O:$O, "Completed") -> 0 | AA32: =IF(Y32=0, 0, Z32/Y32) -> 0
M33: =IF(ISBLANK(L33), "", L33 - $C$4) | U33: =IF(ISBLANK(Settings!D12),"",Settings!D12) -> Research | V33: =IF(OR(ISBLANK(U33), U33=""), "", COUNTIF('Tasks Board'!$H:$H, U33)) -> 0 | X33: 22 | Y33: =COUNTIFS($L:$L, DATE($X$4, $X$9, $X33)) -> 0 | Z33: =COUNTIFS($L:$L, DATE($X$4, $X$9, $X33), $O:$O, "Completed") -> 0 | AA33: =IF(Y33=0, 0, Z33/Y33) -> 0
M34: =IF(ISBLANK(L34), "", L34 - $C$4) | U34: =IF(ISBLANK(Settings!D13),"",Settings!D13) -> Sales | V34: =IF(OR(ISBLANK(U34), U34=""), "", COUNTIF('Tasks Board'!$H:$H, U34)) -> 0 | X34: 23 | Y34: =COUNTIFS($L:$L, DATE($X$4, $X$9, $X34)) -> 0 | Z34: =COUNTIFS($L:$L, DATE($X$4, $X$9, $X34), $O:$O, "Completed") -> 0 | AA34: =IF(Y34=0, 0, Z34/Y34) -> 0
M35: =IF(ISBLANK(L35), "", L35 - $C$4) | X35: 24 | Y35: =COUNTIFS($L:$L, DATE($X$4, $X$9, $X35)) -> 0 | Z35: =COUNTIFS($L:$L, DATE($X$4, $X$9, $X35), $O:$O, "Completed") -> 0 | AA35: =IF(Y35=0, 0, Z35/Y35) -> 0
M36: =IF(ISBLANK(L36), "", L36 - $C$4) | U36: Distribution of Tasks by Priority | X36: 25 | Y36: =COUNTIFS($L:$L, DATE($X$4, $X$9, $X36)) -> 0 | Z36: =COUNTIFS($L:$L, DATE($X$4, $X$9, $X36), $O:$O, "Completed") -> 0 | AA36: =IF(Y36=0, 0, Z36/Y36) -> 0
M37: =IF(ISBLANK(L37), "", L37 - $C$4) | U37: Priority | V37: Number of Tasks | X37: 26 | Y37: =COUNTIFS($L:$L, DATE($X$4, $X$9, $X37)) -> 0 | Z37: =COUNTIFS($L:$L, DATE($X$4, $X$9, $X37), $O:$O, "Completed") -> 0 | AA37: =IF(Y37=0, 0, Z37/Y37) -> 0
M38: =IF(ISBLANK(L38), "", L38 - $C$4) | U38: =IF(ISBLANK(Settings!L4),"",Settings!L4) -> Low | V38: =IF(OR(ISBLANK(U38), U38=""), "", COUNTIF('Tasks Board'!$I:$I, U38)) -> 0 | X38: 27 | Y38: =COUNTIFS($L:$L, DATE($X$4, $X$9, $X38)) -> 0 | Z38: =COUNTIFS($L:$L, DATE($X$4, $X$9, $X38), $O:$O, "Completed") -> 0 | AA38: =IF(Y38=0, 0, Z38/Y38) -> 0
M39: =IF(ISBLANK(L39), "", L39 - $C$4) | U39: =IF(ISBLANK(Settings!L5),"",Settings!L5) -> Medium | V39: =IF(OR(ISBLANK(U39), U39=""), "", COUNTIF('Tasks Board'!$I:$I, U39)) -> 0 | X39: 28 | Y39: =COUNTIFS($L:$L, DATE($X$4, $X$9, $X39)) -> 0 | Z39: =COUNTIFS($L:$L, DATE($X$4, $X$9, $X39), $O:$O, "Completed") -> 0 | AA39: =IF(Y39=0, 0, Z39/Y39) -> 0
M40: =IF(ISBLANK(L40), "", L40 - $C$4) | U40: =IF(ISBLANK(Settings!L6),"",Settings!L6) -> High | V40: =IF(OR(ISBLANK(U40), U40=""), "", COUNTIF('Tasks Board'!$I:$I, U40)) -> 0 | X40: 29 | Y40: =COUNTIFS($L:$L, DATE($X$4, $X$9, $X40)) -> 0 | Z40: =COUNTIFS($L:$L, DATE($X$4, $X$9, $X40), $O:$O, "Completed") -> 0 | AA40: =IF(Y40=0, 0, Z40/Y40) -> 0
M41: =IF(ISBLANK(L41), "", L41 - $C$4) | U41: =IF(ISBLANK(Settings!L7),"",Settings!L7) -> Very High | V41: =IF(OR(ISBLANK(U41), U41=""), "", COUNTIF('Tasks Board'!$I:$I, U41)) -> 0 | X41: 30 | Y41: =COUNTIFS($L:$L, DATE($X$4, $X$9, $X41)) -> 0 | Z41: =COUNTIFS($L:$L, DATE($X$4, $X$9, $X41), $O:$O, "Completed") -> 0 | AA41: =IF(Y41=0, 0, Z41/Y41) -> 0
...

Sheet Gantt Chart
C1: TIMELINE GANTT CHART
C3: Date Today | F3: Overall Progress | L3: Chart Customization | P3: Timeline Visualization
C4: =TODAY() -> 46232 | L4: Begin Tasks: | M4: 45292 | P4: ="Week " & ROUNDUP((P7 - $M$4 + WEEKDAY($M$4, 2)) / 7, 0) -> Week 1 | W4: ="Week " & ROUNDUP((W7 - $M$4 + WEEKDAY($M$4, 2)) / 7, 0) -> Week 2 | AD4: ="Week " & ROUNDUP((AD7 - $M$4 + WEEKDAY($M$4, 2)) / 7, 0) -> Week 3 | AK4: ="Week " & ROUNDUP((AK7 - $M$4 + WEEKDAY($M$4, 2)) / 7, 0) -> Week 4 | AR4: ="Week " & ROUNDUP((AR7 - $M$4 + WEEKDAY($M$4, 2)) / 7, 0) -> Week 5
C5: =C4 -> 46232 | L5: Display Week No.: | M5: 1
F6: =IF(COUNTIFS(E:E, "<>") = 0, "", AVERAGEIFS(L:L, E:E, "<>")) -> #DIV/0! | G6: =100%-F6 -> #DIV/0! | P6: =P7 -> 45292 | W6: =W7 -> 45299 | AD6: =AD7 -> 45306 | AK6: =AK7 -> 45313 | AR6: =AR7 -> 45320
C7: Person Assigned | D7: Task ID | E7: Task Description | G7: Category | H7: Priority | I7: Department | J7: Status | L7: Progress | M7: Task Start Date | N7: Task Due Date | P7: =task_start-WEEKDAY(task_start,3)+(display_week-1)*7 -> 45292 | Q7: =P7+1 -> 45293 | R7: =Q7+1 -> 45294 | S7: =R7+1 -> 45295 | T7: =S7+1 -> 45296 | U7: =T7+1 -> 45297 | V7: =U7+1 -> 45298 | W7: =V7+1 -> 45299 | X7: =W7+1 -> 45300 | ... AX7: =AW7+1 -> 45326
P8: =LEFT(TEXT(P7,"ddd"),1) -> M | Q8: =LEFT(TEXT(Q7,"ddd"),1) -> T | R8: =LEFT(TEXT(R7,"ddd"),1) -> W | S8: =LEFT(TEXT(S7,"ddd"),1) -> T | T8: =LEFT(TEXT(T7,"ddd"),1) -> F | U8: =LEFT(TEXT(U7,"ddd"),1) -> S | V8: =LEFT(TEXT(V7,"ddd"),1) -> S | W8: =LEFT(TEXT(W7,"ddd"),1) -> M | ... AX8: =LEFT(TEXT(AX7,"ddd"),1) -> S
P9: =IF(AND(P$7>=$M9,P$7<=$N9),IF($L9=100%,$L9,$H9),"") | Q9: =IF(AND(Q$7>=$M9,Q$7<=$N9),IF($L9=100%,$L9,$H9),"") | R9: =IF(AND(R$7>=$M9,R$7<=$N9),IF($L9=100%,$L9,$H9),"") | S9: =IF(AND(S$7>=$M9,S$7<=$N9),IF($L9=100%,$L9,$H9),"") | T9: =IF(AND(T$7>=$M9,T$7<=$N9),IF($L9=100%,$L9,$H9),"") | U9: =IF(AND(U$7>=$M9,U$7<=$N9),IF($L9=100%,$L9,$H9),"") | V9: =IF(AND(V$7>=$M9,V$7<=$N9),IF($L9=100%,$L9,$H9),"") | W9: =IF(AND(W$7>=$M9,W$7<=$N9),IF($L9=100%,$L9,$H9),"") | ... AX9: =IF(AND(AX$7>=$M9,AX$7<=$N9),IF($L9=100%,$L9,$H9),"")
P10: =IF(AND(P$7>=$M10,P$7<=$N10),IF($L10=100%,$L10,$H10),"") | Q10: =IF(AND(Q$7>=$M10,Q$7<=$N10),IF($L10=100%,$L10,$H10),"") | R10: =IF(AND(R$7>=$M10,R$7<=$N10),IF($L10=100%,$L10,$H10),"") | S10: =IF(AND(S$7>=$M10,S$7<=$N10),IF($L10=100%,$L10,$H10),"") | T10: =IF(AND(T$7>=$M10,T$7<=$N10),IF($L10=100%,$L10,$H10),"") | U10: =IF(AND(U$7>=$M10,U$7<=$N10),IF($L10=100%,$L10,$H10),"") | V10: =IF(AND(V$7>=$M10,V$7<=$N10),IF($L10=100%,$L10,$H10),"") | W10: =IF(AND(W$7>=$M10,W$7<=$N10),IF($L10=100%,$L10,$H10),"") | ... AX10: =IF(AND(AX$7>=$M10,AX$7<=$N10),IF($L10=100%,$L10,$H10),"")
P11: =IF(AND(P$7>=$M11,P$7<=$N11),IF($L11=100%,$L11,$H11),"") | Q11: =IF(AND(Q$7>=$M11,Q$7<=$N11),IF($L11=100%,$L11,$H11),"") | R11: =IF(AND(R$7>=$M11,R$7<=$N11),IF($L11=100%,$L11,$H11),"") | S11: =IF(AND(S$7>=$M11,S$7<=$N11),IF($L11=100%,$L11,$H11),"") | T11: =IF(AND(T$7>=$M11,T$7<=$N11),IF($L11=100%,$L11,$H11),"") | U11: =IF(AND(U$7>=$M11,U$7<=$N11),IF($L11=100%,$L11,$H11),"") | V11: =IF(AND(V$7>=$M11,V$7<=$N11),IF($L11=100%,$L11,$H11),"") | W11: =IF(AND(W$7>=$M11,W$7<=$N11),IF($L11=100%,$L11,$H11),"") | ... AX11: =IF(AND(AX$7>=$M11,AX$7<=$N11),IF($L11=100%,$L11,$H11),"")
P12: =IF(AND(P$7>=$M12,P$7<=$N12),IF($L12=100%,$L12,$H12),"") | Q12: =IF(AND(Q$7>=$M12,Q$7<=$N12),IF($L12=100%,$L12,$H12),"") | R12: =IF(AND(R$7>=$M12,R$7<=$N12),IF($L12=100%,$L12,$H12),"") | S12: =IF(AND(S$7>=$M12,S$7<=$N12),IF($L12=100%,$L12,$H12),"") | T12: =IF(AND(T$7>=$M12,T$7<=$N12),IF($L12=100%,$L12,$H12),"") | U12: =IF(AND(U$7>=$M12,U$7<=$N12),IF($L12=100%,$L12,$H12),"") | V12: =IF(AND(V$7>=$M12,V$7<=$N12),IF($L12=100%,$L12,$H12),"") | W12: =IF(AND(W$7>=$M12,W$7<=$N12),IF($L12=100%,$L12,$H12),"") | ... AX12: =IF(AND(AX$7>=$M12,AX$7<=$N12),IF($L12=100%,$L12,$H12),"")
P13: =IF(AND(P$7>=$M13,P$7<=$N13),IF($L13=100%,$L13,$H13),"") | Q13: =IF(AND(Q$7>=$M13,Q$7<=$N13),IF($L13=100%,$L13,$H13),"") | R13: =IF(AND(R$7>=$M13,R$7<=$N13),IF($L13=100%,$L13,$H13),"") | S13: =IF(AND(S$7>=$M13,S$7<=$N13),IF($L13=100%,$L13,$H13),"") | T13: =IF(AND(T$7>=$M13,T$7<=$N13),IF($L13=100%,$L13,$H13),"") | U13: =IF(AND(U$7>=$M13,U$7<=$N13),IF($L13=100%,$L13,$H13),"") | V13: =IF(AND(V$7>=$M13,V$7<=$N13),IF($L13=100%,$L13,$H13),"") | W13: =IF(AND(W$7>=$M13,W$7<=$N13),IF($L13=100%,$L13,$H13),"") | ... AX13: =IF(AND(AX$7>=$M13,AX$7<=$N13),IF($L13=100%,$L13,$H13),"")
P14: =IF(AND(P$7>=$M14,P$7<=$N14),IF($L14=100%,$L14,$H14),"") | Q14: =IF(AND(Q$7>=$M14,Q$7<=$N14),IF($L14=100%,$L14,$H14),"") | R14: =IF(AND(R$7>=$M14,R$7<=$N14),IF($L14=100%,$L14,$H14),"") | S14: =IF(AND(S$7>=$M14,S$7<=$N14),IF($L14=100%,$L14,$H14),"") | T14: =IF(AND(T$7>=$M14,T$7<=$N14),IF($L14=100%,$L14,$H14),"") | U14: =IF(AND(U$7>=$M14,U$7<=$N14),IF($L14=100%,$L14,$H14),"") | V14: =IF(AND(V$7>=$M14,V$7<=$N14),IF($L14=100%,$L14,$H14),"") | W14: =IF(AND(W$7>=$M14,W$7<=$N14),IF($L14=100%,$L14,$H14),"") | ... AX14: =IF(AND(AX$7>=$M14,AX$7<=$N14),IF($L14=100%,$L14,$H14),"")
P15: =IF(AND(P$7>=$M15,P$7<=$N15),IF($L15=100%,$L15,$H15),"") | Q15: =IF(AND(Q$7>=$M15,Q$7<=$N15),IF($L15=100%,$L15,$H15),"") | R15: =IF(AND(R$7>=$M15,R$7<=$N15),IF($L15=100%,$L15,$H15),"") | S15: =IF(AND(S$7>=$M15,S$7<=$N15),IF($L15=100%,$L15,$H15),"") | T15: =IF(AND(T$7>=$M15,T$7<=$N15),IF($L15=100%,$L15,$H15),"") | U15: =IF(AND(U$7>=$M15,U$7<=$N15),IF($L15=100%,$L15,$H15),"") | V15: =IF(AND(V$7>=$M15,V$7<=$N15),IF($L15=100%,$L15,$H15),"") | W15: =IF(AND(W$7>=$M15,W$7<=$N15),IF($L15=100%,$L15,$H15),"") | ... AX15: =IF(AND(AX$7>=$M15,AX$7<=$N15),IF($L15=100%,$L15,$H15),"")
P16: =IF(AND(P$7>=$M16,P$7<=$N16),IF($L16=100%,$L16,$H16),"") | Q16: =IF(AND(Q$7>=$M16,Q$7<=$N16),IF($L16=100%,$L16,$H16),"") | R16: =IF(AND(R$7>=$M16,R$7<=$N16),IF($L16=100%,$L16,$H16),"") | S16: =IF(AND(S$7>=$M16,S$7<=$N16),IF($L16=100%,$L16,$H16),"") | T16: =IF(AND(T$7>=$M16,T$7<=$N16),IF($L16=100%,$L16,$H16),"") | U16: =IF(AND(U$7>=$M16,U$7<=$N16),IF($L16=100%,$L16,$H16),"") | V16: =IF(AND(V$7>=$M16,V$7<=$N16),IF($L16=100%,$L16,$H16),"") | W16: =IF(AND(W$7>=$M16,W$7<=$N16),IF($L16=100%,$L16,$H16),"") | ... AX16: =IF(AND(AX$7>=$M16,AX$7<=$N16),IF($L16=100%,$L16,$H16),"")
P17: =IF(AND(P$7>=$M17,P$7<=$N17),IF($L17=100%,$L17,$H17),"") | Q17: =IF(AND(Q$7>=$M17,Q$7<=$N17),IF($L17=100%,$L17,$H17),"") | R17: =IF(AND(R$7>=$M17,R$7<=$N17),IF($L17=100%,$L17,$H17),"") | S17: =IF(AND(S$7>=$M17,S$7<=$N17),IF($L17=100%,$L17,$H17),"") | T17: =IF(AND(T$7>=$M17,T$7<=$N17),IF($L17=100%,$L17,$H17),"") | U17: =IF(AND(U$7>=$M17,U$7<=$N17),IF($L17=100%,$L17,$H17),"") | V17: =IF(AND(V$7>=$M17,V$7<=$N17),IF($L17=100%,$L17,$H17),"") | W17: =IF(AND(W$7>=$M17,W$7<=$N17),IF($L17=100%,$L17,$H17),"") | ... AX17: =IF(AND(AX$7>=$M17,AX$7<=$N17),IF($L17=100%,$L17,$H17),"")
P18: =IF(AND(P$7>=$M18,P$7<=$N18),IF($L18=100%,$L18,$H18),"") | Q18: =IF(AND(Q$7>=$M18,Q$7<=$N18),IF($L18=100%,$L18,$H18),"") | R18: =IF(AND(R$7>=$M18,R$7<=$N18),IF($L18=100%,$L18,$H18),"") | S18: =IF(AND(S$7>=$M18,S$7<=$N18),IF($L18=100%,$L18,$H18),"") | T18: =IF(AND(T$7>=$M18,T$7<=$N18),IF($L18=100%,$L18,$H18),"") | U18: =IF(AND(U$7>=$M18,U$7<=$N18),IF($L18=100%,$L18,$H18),"") | V18: =IF(AND(V$7>=$M18,V$7<=$N18),IF($L18=100%,$L18,$H18),"") | W18: =IF(AND(W$7>=$M18,W$7<=$N18),IF($L18=100%,$L18,$H18),"") | ... AX18: =IF(AND(AX$7>=$M18,AX$7<=$N18),IF($L18=100%,$L18,$H18),"")
P19: =IF(AND(P$7>=$M19,P$7<=$N19),IF($L19=100%,$L19,$H19),"") | Q19: =IF(AND(Q$7>=$M19,Q$7<=$N19),IF($L19=100%,$L19,$H19),"") | R19: =IF(AND(R$7>=$M19,R$7<=$N19),IF($L19=100%,$L19,$H19),"") | S19: =IF(AND(S$7>=$M19,S$7<=$N19),IF($L19=100%,$L19,$H19),"") | T19: =IF(AND(T$7>=$M19,T$7<=$N19),IF($L19=100%,$L19,$H19),"") | U19: =IF(AND(U$7>=$M19,U$7<=$N19),IF($L19=100%,$L19,$H19),"") | V19: =IF(AND(V$7>=$M19,V$7<=$N19),IF($L19=100%,$L19,$H19),"") | W19: =IF(AND(W$7>=$M19,W$7<=$N19),IF($L19=100%,$L19,$H19),"") | ... AX19: =IF(AND(AX$7>=$M19,AX$7<=$N19),IF($L19=100%,$L19,$H19),"")
P20: =IF(AND(P$7>=$M20,P$7<=$N20),IF($L20=100%,$L20,$H20),"") | Q20: =IF(AND(Q$7>=$M20,Q$7<=$N20),IF($L20=100%,$L20,$H20),"") | R20: =IF(AND(R$7>=$M20,R$7<=$N20),IF($L20=100%,$L20,$H20),"") | S20: =IF(AND(S$7>=$M20,S$7<=$N20),IF($L20=100%,$L20,$H20),"") | T20: =IF(AND(T$7>=$M20,T$7<=$N20),IF($L20=100%,$L20,$H20),"") | U20: =IF(AND(U$7>=$M20,U$7<=$N20),IF($L20=100%,$L20,$H20),"") | V20: =IF(AND(V$7>=$M20,V$7<=$N20),IF($L20=100%,$L20,$H20),"") | W20: =IF(AND(W$7>=$M20,W$7<=$N20),IF($L20=100%,$L20,$H20),"") | ... AX20: =IF(AND(AX$7>=$M20,AX$7<=$N20),IF($L20=100%,$L20,$H20),"")
... P1000: =IF(AND(P$7>=$M1000,P$7<=$N1000),IF($L1000=100%,$L1000,$H1000),"") | Q1000: =IF(AND(Q$7>=$M1000,Q$7<=$N1000),IF($L1000=100%,$L1000,$H1000),"") | R1000: =IF(AND(R$7>=$M1000,R$7<=$N1000),IF($L1000=100%,$L1000,$H1000),"") | S1000: =IF(AND(S$7>=$M1000,S$7<=$N1000),IF($L1000=100%,$L1000,$H1000),"") | T1000: =IF(AND(T$7>=$M1000,T$7<=$N1000),IF($L1000=100%,$L1000,$H1000),"") | U1000: =IF(AND(U$7>=$M1000,U$7<=$N1000),IF($L1000=100%,$L1000,$H1000),"") | V1000: =IF(AND(V$7>=$M1000,V$7<=$N1000),IF($L1000=100%,$L1000,$H1000),"") | W1000: =IF(AND(W$7>=$M1000,W$7<=$N1000),IF($L1000=100%,$L1000,$H1000),"") | ... AX1000: =IF(AND(AX$7>=$M1000,AX$7<=$N1000),IF($L1000=100%,$L1000,$H1000),"")

Sheet Kanban Board
C1: KANBAN BOARD
C3: =Settings!J4 -> Not Started | J3: =Settings!J5 -> In Progress | Q3: =Settings!J6 -> On Hold | X3: =Settings!J7 -> Active | AE3: =Settings!J8 -> In Review | AL3: =Settings!J9 -> Completed | AS3: =Settings!J10 -> Overdue | AZ3: =Settings!J11 -> Cancelled | BG3: =Settings!J12 -> 0 | BN3: =Settings!J13 -> 0
B5: {=IFERROR( INDEX('Gantt Chart'!$D$9:$D$1000, SMALL( IF(('Gantt Chart'!$J$9:$J$1000=$C$3) * ('Gantt Chart'!$L$9:$L$1000<1), ROW('Gantt Chart'!$D$9:$D$1000)-MIN(ROW('Gantt Chart'!$D$9:$D$1000))+1, ""), ROW(A1)) ), "")} | D5: =IFERROR(INDEX('Gantt Chart'!$H$9:$H$1000, MATCH($G8, 'Gantt Chart'!$D$9:$D$1000, 0)), "") | E5: =IFERROR(VLOOKUP($G8, 'Gantt Chart'!$D$9:$E$1000, 2, FALSE), "") | I5: {=IFERROR( INDEX('Gantt Chart'!$D$9:$D$1000, SMALL( IF(('Gantt Chart'!$J$9:$J$1000=$J$3) * ('Gantt Chart'!$L$9:$L$1000<1), ROW('Gantt Chart'!$D$9:$D$1000)-MIN(ROW('Gantt Chart'!$D$9:$D$1000))+1, ""), ROW(A1)) ), "")} | K5: =IFERROR(INDEX('Gantt Chart'!$H$9:$H$1000, MATCH($N8, 'Gantt Chart'!$D$9:$D$1000, 0)), "") | L5: =IFERROR(VLOOKUP($N8, 'Gantt Chart'!$D$9:$E$1000, 2, FALSE), "") | P5: {=IFERROR( INDEX('Gantt Chart'!$D$9:$D$1000, SMALL( IF(('Gantt Chart'!$J$9:$J$1000=$Q$3) * ('Gantt Chart'!$L$9:$L$1000<1), ROW('Gantt Chart'!$D$9:$D$1000)-MIN(ROW('Gantt Chart'!$D$9:$D$1000))+1, ""), ROW(A1)) ), "")} | R5: =IFERROR(INDEX('Gantt Chart'!$H$9:$H$1000, MATCH($U8, 'Gantt Chart'!$D$9:$D$1000, 0)), "") | S5: =IFERROR(VLOOKUP($U8, 'Gantt Chart'!$D$9:$E$1000, 2, FALSE), "") | W5: {=IFERROR( INDEX('Gantt Chart'!$D$9:$D$1000, SMALL( IF(('Gantt Chart'!$J$9:$J$1000=$X$3) * ('Gantt Chart'!$L$9:$L$1000<1), ROW('Gantt Chart'!$D$9:$D$1000)-MIN(ROW('Gantt Chart'!$D$9:$D$1000))+1, ""), ROW(A1)) ), "")} | Y5: =IFERROR(INDEX('Gantt Chart'!$H$9:$H$1000, MATCH($AB8, 'Gantt Chart'!$D$9:$D$1000, 0)), "") | Z5: =IFERROR(VLOOKUP($AB8, 'Gantt Chart'!$D$9:$E$1000, 2, FALSE), "") | AD5: {=IFERROR( INDEX('Gantt Chart'!$D$9:$D$1000, SMALL( IF(('Gantt Chart'!$J$9:$J$1000=$AE$3) * ('Gantt Chart'!$L$9:$L$1000<1), ROW('Gantt Chart'!$D$9:$D$1000)-MIN(ROW('Gantt Chart'!$D$9:$D$1000))+1, ""), ROW(A1)) ), "")} | AF5: =IFERROR(INDEX('Gantt Chart'!$H$9:$H$1000, MATCH($AI8, 'Gantt Chart'!$D$9:$D$1000, 0)), "") | AG5: =IFERROR(VLOOKUP($AI8, 'Gantt Chart'!$D$9:$E$1000, 2, FALSE), "") | AK5: {=IFERROR( INDEX('Gantt Chart'!$D$9:$D$1000, SMALL( IF(('Gantt Chart'!$J$9:$J$1000=$AL$3) * ('Gantt Chart'!$L$9:$L$1000<1), ROW('Gantt Chart'!$D$9:$D$1000)-MIN(ROW('Gantt Chart'!$D$9:$D$1000))+1, ""), ROW(A1)) ), "")} | AM5: =IFERROR(INDEX('Gantt Chart'!$H$9:$H$1000, MATCH($AP8, 'Gantt Chart'!$D$9:$D$1000, 0)), "") | AN5: =IFERROR(VLOOKUP($AP8, 'Gantt Chart'!$D$9:$E$1000, 2, FALSE), "") | AR5: {=IFERROR( INDEX('Gantt Chart'!$D$9:$D$1000, SMALL( IF(('Gantt Chart'!$J$9:$J$1000=$AS$3) * ('Gantt Chart'!$L$9:$L$1000<1), ROW('Gantt Chart'!$D$9:$D$1000)-MIN(ROW('Gantt Chart'!$D$9:$D$1000))+1, ""), ROW(A1)) ), "")} | AT5: =IFERROR(INDEX('Gantt Chart'!$H$9:$H$1000, MATCH($AW8, 'Gantt Chart'!$D$9:$D$1000, 0)), "") | AU5: =IFERROR(VLOOKUP($AW8, 'Gantt Chart'!$D$9:$E$1000, 2, FALSE), "") | AY5: {=IFERROR( INDEX('Gantt Chart'!$D$9:$D$1000, SMALL( IF(('Gantt Chart'!$J$9:$J$1000=$AZ$3) * ('Gantt Chart'!$L$9:$L$1000<1), ROW('Gantt Chart'!$D$9:$D$1000)-MIN(ROW('Gantt Chart'!$D$9:$D$1000))+1, ""), ROW(A1)) ), "")} | BA5: =IFERROR(INDEX('Gantt Chart'!$H$9:$H$1000, MATCH($BD8, 'Gantt Chart'!$D$9:$D$1000, 0)), "") | BB5: =IFERROR(VLOOKUP($BD8, 'Gantt Chart'!$D$9:$E$1000, 2, FALSE), "") | BF5: {=IFERROR( INDEX('Gantt Chart'!$D$9:$D$1000, SMALL( IF(('Gantt Chart'!$J$9:$J$1000=$BG$3) * ('Gantt Chart'!$L$9:$L$1000<1), ROW('Gantt Chart'!$D$9:$D$1000)-MIN(ROW('Gantt Chart'!$D$9:$D$1000))+1, ""), ROW(A1)) ), "")} -> 0 | BH5: =IFERROR(INDEX('Gantt Chart'!$H$9:$H$1000, MATCH($BK8, 'Gantt Chart'!$D$9:$D$1000, 0)), "") | BI5: =IFERROR(VLOOKUP($BK8, 'Gantt Chart'!$D$9:$E$1000, 2, FALSE), "") | BM5: {=IFERROR( INDEX('Gantt Chart'!$D$9:$D$1000, SMALL( IF(('Gantt Chart'!$J$9:$J$1000=$BN$3) * ('Gantt Chart'!$L$9:$L$1000<1), ROW('Gantt Chart'!$D$9:$D$1000)-MIN(ROW('Gantt Chart'!$D$9:$D$1000))+1, ""), ROW(A1)) ), "")} -> 0 | BO5: =IFERROR(INDEX('Gantt Chart'!$H$9:$H$1000, MATCH($BR8, 'Gantt Chart'!$D$9:$D$1000, 0)), "") | BP5: =IFERROR(VLOOKUP($BR8, 'Gantt Chart'!$D$9:$E$1000, 2, FALSE), "")
B6: {=IFERROR( INDEX('Gantt Chart'!$D$9:$D$1000, SMALL( IF(('Gantt Chart'!$J$9:$J$1000=$C$3) * ('Gantt Chart'!$L$9:$L$1000<1), ROW('Gantt Chart'!$D$9:$D$1000)-MIN(ROW('Gantt Chart'!$D$9:$D$1000))+1, ""), ROW(A2)) ), "")} | E6: =IFERROR(INDEX('Gantt Chart'!$C$9:$C$1000, MATCH($G8, 'Gantt Chart'!$D$9:$D$1000, 0)), "") | I6: {=IFERROR( INDEX('Gantt Chart'!$D$9:$D$1000, SMALL( IF(('Gantt Chart'!$J$9:$J$1000=$J$3) * ('Gantt Chart'!$L$9:$L$1000<1), ROW('Gantt Chart'!$D$9:$D$1000)-MIN(ROW('Gantt Chart'!$D$9:$D$1000))+1, ""), ROW(A2)) ), "")} | L6: =IFERROR(INDEX('Gantt Chart'!$C$9:$C$1000, MATCH($N8, 'Gantt Chart'!$D$9:$D$1000, 0)), "") | P6: {=IFERROR( INDEX('Gantt Chart'!$D$9:$D$1000, SMALL( IF(('Gantt Chart'!$J$9:$J$1000=$Q$3) * ('Gantt Chart'!$L$9:$L$1000<1), ROW('Gantt Chart'!$D$9:$D$1000)-MIN(ROW('Gantt Chart'!$D$9:$D$1000))+1, ""), ROW(A2)) ), "")} | S6: =IFERROR(INDEX('Gantt Chart'!$C$9:$C$1000, MATCH($U8, 'Gantt Chart'!$D$9:$D$1000, 0)), "") | W6: {=IFERROR( INDEX('Gantt Chart'!$D$9:$D$1000, SMALL( IF(('Gantt Chart'!$J$9:$J$1000=$X$3) * ('Gantt Chart'!$L$9:$L$1000<1), ROW('Gantt Chart'!$D$9:$D$1000)-MIN(ROW('Gantt Chart'!$D$9:$D$1000))+1, ""), ROW(A2)) ), "")} | Z6: =IFERROR(INDEX('Gantt Chart'!$C$9:$C$1000, MATCH($AB8, 'Gantt Chart'!$D$9:$D$1000, 0)), "") | AD6: {=IFERROR( INDEX('Gantt Chart'!$D$9:$D$1000, SMALL( IF(('Gantt Chart'!$J$9:$J$1000=$AE$3) * ('Gantt Chart'!$L$9:$L$1000<1), ROW('Gantt Chart'!$D$9:$D$1000)-MIN(ROW('Gantt Chart'!$D$9:$D$1000))+1, ""), ROW(A2)) ), "")} | AG6: =IFERROR(INDEX('Gantt Chart'!$C$9:$C$1000, MATCH($AI8, 'Gantt Chart'!$D$9:$D$1000, 0)), "") | AK6: {=IFERROR( INDEX('Gantt Chart'!$D$9:$D$1000, SMALL( IF(('Gantt Chart'!$J$9:$J$1000=$AL$3) * ('Gantt Chart'!$L$9:$L$1000<1), ROW('Gantt Chart'!$D$9:$D$1000)-MIN(ROW('Gantt Chart'!$D$9:$D$1000))+1, ""), ROW(A2)) ), "")} | AN6: =IFERROR(INDEX('Gantt Chart'!$C$9:$C$1000, MATCH($AP8, 'Gantt Chart'!$D$9:$D$1000, 0)), "") | AR6: {=IFERROR( INDEX('Gantt Chart'!$D$9:$D$1000, SMALL( IF(('Gantt Chart'!$J$9:$J$1000=$AS$3) * ('Gantt Chart'!$L$9:$L$1000<1), ROW('Gantt Chart'!$D$9:$D$1000)-MIN(ROW('Gantt Chart'!$D$9:$D$1000))+1, ""), ROW(A2)) ), "")} | AU6: =IFERROR(INDEX('Gantt Chart'!$C$9:$C$1000, MATCH($AW8, 'Gantt Chart'!$D$9:$D$1000, 0)), "") | AY6: {=IFERROR( INDEX('Gantt Chart'!$D$9:$D$1000, SMALL( IF(('Gantt Chart'!$J$9:$J$1000=$AZ$3) * ('Gantt Chart'!$L$9:$L$1000<1), ROW('Gantt Chart'!$D$9:$D$1000)-MIN(ROW('Gantt Chart'!$D$9:$D$1000))+1, ""), ROW(A2)) ), "")} | BB6: =IFERROR(INDEX('Gantt Chart'!$C$9:$C$1000, MATCH($BD8, 'Gantt Chart'!$D$9:$D$1000, 0)), "") | BF6: {=IFERROR( INDEX('Gantt Chart'!$D$9:$D$1000, SMALL( IF(('Gantt Chart'!$J$9:$J$1000=$BG$3) * ('Gantt Chart'!$L$9:$L$1000<1), ROW('Gantt Chart'!$D$9:$D$1000)-MIN(ROW('Gantt Chart'!$D$9:$D$1000))+1, ""), ROW(A2)) ), "")} -> 0 | BI6: =IFERROR(INDEX('Gantt Chart'!$C$9:$C$1000, MATCH($BK8, 'Gantt Chart'!$D$9:$D$1000, 0)), "") | BM6: {=IFERROR( INDEX('Gantt Chart'!$D$9:$D$1000, SMALL( IF(('Gantt Chart'!$J$9:$J$1000=$BN$3) * ('Gantt Chart'!$L$9:$L$1000<1), ROW('Gantt Chart'!$D$9:$D$1000)-MIN(ROW('Gantt Chart'!$D$9:$D$1000))+1, ""), ROW(A2)) ), "")} -> 0 | BP6: =IFERROR(INDEX('Gantt Chart'!$C$9:$C$1000, MATCH($BR8, 'Gantt Chart'!$D$9:$D$1000, 0)), "")
